<?xml version="1.0" encoding="UTF-8"?>
<!-- Generated by org.testng.reporters.JUnitXMLReporter -->
<testsuite ignored="0" hostname="LAPTOP-LK1GIISB" failures="6" tests="23" name="Default test" time="157.487" errors="0" timestamp="2025-09-04T17:14:30 IST">
  <testcase classname="com.functional.tests.ContactUs_Functional" name="tc_cu_01_nameAcceptsValid" time="0.577"/>
  <testcase classname="com.functional.tests.ContactUs_Functional" name="tc_cu_02_nameRejectsInvalid" time="0.337"/>
  <testcase classname="com.functional.tests.ContactUs_Functional" name="tc_cu_03_emailAcceptsValid" time="0.24"/>
  <testcase classname="com.functional.tests.ContactUs_Functional" name="tc_cu_04_emailRejectsInvalid" time="0.212"/>
  <testcase classname="com.functional.tests.ContactUs_Functional" name="tc_cu_05_subjectAcceptsValid" time="0.252"/>
  <testcase classname="com.functional.tests.ContactUs_Functional" name="tc_cu_06_subjectRejectsInvalid" time="0.327"/>
  <testcase classname="com.functional.tests.ContactUs_Functional" name="tc_cu_07_messageFieldAcceptsText" time="0.182"/>
  <testcase classname="com.functional.tests.ContactUs_Functional" name="tc_cu_08_chooseFileClickable" time="0.076"/>
  <testcase classname="com.functional.tests.ContactUs_Functional" name="tc_cu_09_chosenFileAppears" time="0.052"/>
  <testcase classname="com.functional.tests.ContactUs_Functional" name="tc_cu_10_nameRejectsSpecialCharsStrict" time="0.148"/>
  <testcase classname="com.functional.tests.ContactUs_Functional" name="tc_cu_11_feedbackMailLinkIsMailto" time="0.021"/>
  <testcase classname="com.functional.tests.ContactUs_Functional" name="tc_cu_12_footerSubValid" time="0.408"/>
  <testcase classname="com.functional.tests.ContactUs_Functional" name="tc_cu_13_footerSubInvalid" time="0.368"/>
  <testcase classname="com.functional.tests.ContactUs_Functional" name="tc_cu_14_footerSubBlank" time="0.348"/>
  <testcase classname="com.functional.tests.ContactUs_Functional" name="tc_cu_15_footerSubDuplicate" time="11.439">
    <failure type="org.openqa.selenium.TimeoutException" message="Expected condition failed: waiting for visibility of element located by By.xpath: //*[contains(translate(.,&amp;apos;ABCDEFGHIJKLMNOPQRSTUVWXYZ&amp;apos;,&amp;apos;abcdefghijklmnopqrstuvwxyz&amp;apos;),&amp;apos;already&amp;apos;) or contains(.,&amp;apos;exists&amp;apos;) or contains(@class,&amp;apos;alert-warning&amp;apos;) or contains(@class,&amp;apos;alert-danger&amp;apos;)] (tried for 6 second(s) with 500 milliseconds interval)
Build info: version: &amp;apos;4.35.0&amp;apos;, revision: &amp;apos;1c58e5028b&amp;apos;
System info: os.name: &amp;apos;Windows 11&amp;apos;, os.arch: &amp;apos;amd64&amp;apos;, os.version: &amp;apos;10.0&amp;apos;, java.version: &amp;apos;21.0.7&amp;apos;
Driver info: org.openqa.selenium.chrome.ChromeDriver
Capabilities {acceptInsecureCerts: false, browserName: chrome, browserVersion: 139.0.7258.155, chrome: {chromedriverVersion: 139.0.7258.154 (9e0d6b2b47f..., userDataDir: C:\Users\KEERTH~1\AppData\L...}, fedcm:accounts: true, goog:chromeOptions: {debuggerAddress: localhost:57633}, networkConnectionEnabled: false, pageLoadStrategy: normal, platformName: windows, proxy: Proxy(), se:cdp: ws://localhost:57633/devtoo..., se:cdpVersion: 139.0.7258.155, setWindowRect: true, strictFileInteractability: false, timeouts: {implicit: 0, pageLoad: 300000, script: 30000}, unhandledPromptBehavior: dismiss and notify, webauthn:extension:credBlob: true, webauthn:extension:largeBlob: true, webauthn:extension:minPinLength: true, webauthn:extension:prf: true, webauthn:virtualAuthenticators: true}
Session ID: 834f81b61b4b57428446ab9dfaf37e63">
      <![CDATA[org.openqa.selenium.TimeoutException: Expected condition failed: waiting for visibility of element located by By.xpath: //*[contains(translate(.,'ABCDEFGHIJKLMNOPQRSTUVWXYZ','abcdefghijklmnopqrstuvwxyz'),'already') or contains(.,'exists') or contains(@class,'alert-warning') or contains(@class,'alert-danger')] (tried for 6 second(s) with 500 milliseconds interval)
Build info: version: '4.35.0', revision: '1c58e5028b'
System info: os.name: 'Windows 11', os.arch: 'amd64', os.version: '10.0', java.version: '21.0.7'
Driver info: org.openqa.selenium.chrome.ChromeDriver
Capabilities {acceptInsecureCerts: false, browserName: chrome, browserVersion: 139.0.7258.155, chrome: {chromedriverVersion: 139.0.7258.154 (9e0d6b2b47f..., userDataDir: C:\Users\KEERTH~1\AppData\L...}, fedcm:accounts: true, goog:chromeOptions: {debuggerAddress: localhost:57633}, networkConnectionEnabled: false, pageLoadStrategy: normal, platformName: windows, proxy: Proxy(), se:cdp: ws://localhost:57633/devtoo..., se:cdpVersion: 139.0.7258.155, setWindowRect: true, strictFileInteractability: false, timeouts: {implicit: 0, pageLoad: 300000, script: 30000}, unhandledPromptBehavior: dismiss and notify, webauthn:extension:credBlob: true, webauthn:extension:largeBlob: true, webauthn:extension:minPinLength: true, webauthn:extension:prf: true, webauthn:virtualAuthenticators: true}
Session ID: 834f81b61b4b57428446ab9dfaf37e63
at org.openqa.selenium.support.ui.WebDriverWait.timeoutException(WebDriverWait.java:84)
at org.openqa.selenium.support.ui.FluentWait.until(FluentWait.java:228)
at com.functional.tests.ContactUs_Functional.tc_cu_15_footerSubDuplicate(ContactUs_Functional.java:331)
at java.base/jdk.internal.reflect.DirectMethodHandleAccessor.invoke(DirectMethodHandleAccessor.java:103)
at java.base/java.lang.reflect.Method.invoke(Method.java:580)
at org.testng.internal.invokers.MethodInvocationHelper.invokeMethod(MethodInvocationHelper.java:141)
at org.testng.internal.invokers.TestInvoker.invokeMethod(TestInvoker.java:687)
at org.testng.internal.invokers.TestInvoker.invokeTestMethod(TestInvoker.java:230)
at org.testng.internal.invokers.MethodRunner.runInSequence(MethodRunner.java:63)
at org.testng.internal.invokers.TestInvoker$MethodInvocationAgent.invoke(TestInvoker.java:995)
at org.testng.internal.invokers.TestInvoker.invokeTestMethods(TestInvoker.java:203)
at org.testng.internal.invokers.TestMethodWorker.invokeTestMethods(TestMethodWorker.java:154)
at org.testng.internal.invokers.TestMethodWorker.run(TestMethodWorker.java:134)
at java.base/java.util.ArrayList.forEach(ArrayList.java:1596)
at org.testng.TestRunner.privateRun(TestRunner.java:741)
at org.testng.TestRunner.run(TestRunner.java:616)
at org.testng.SuiteRunner.runTest(SuiteRunner.java:421)
at org.testng.SuiteRunner.runSequentially(SuiteRunner.java:413)
at org.testng.SuiteRunner.privateRun(SuiteRunner.java:373)
at org.testng.SuiteRunner.run(SuiteRunner.java:312)
at org.testng.SuiteRunnerWorker.runSuite(SuiteRunnerWorker.java:52)
at org.testng.SuiteRunnerWorker.run(SuiteRunnerWorker.java:95)
at org.testng.TestNG.runSuitesSequentially(TestNG.java:1274)
at org.testng.TestNG.runSuitesLocally(TestNG.java:1208)
at org.testng.TestNG.runSuites(TestNG.java:1112)
at org.testng.TestNG.run(TestNG.java:1079)
at org.testng.remote.AbstractRemoteTestNG.run(AbstractRemoteTestNG.java:115)
at org.testng.remote.RemoteTestNG.initAndRun(RemoteTestNG.java:293)
at org.testng.remote.RemoteTestNG.main(RemoteTestNG.java:91)
]]>
    </failure>
  </testcase> <!-- tc_cu_15_footerSubDuplicate -->
  <testcase classname="com.functional.tests.ContactUs_Functional" name="tc_cu_16_footerSubEmailOver100Chars" time="0.341">
    <failure type="java.lang.AssertionError" message="Email field should limit or reject &amp;gt;100 chars; observed length=113 expected [true] but found [false]">
      <![CDATA[java.lang.AssertionError: Email field should limit or reject >100 chars; observed length=113 expected [true] but found [false]
at org.testng.Assert.fail(Assert.java:111)
at org.testng.Assert.failNotEquals(Assert.java:1590)
at org.testng.Assert.assertTrue(Assert.java:57)
at com.functional.tests.ContactUs_Functional.tc_cu_16_footerSubEmailOver100Chars(ContactUs_Functional.java:345)
at java.base/jdk.internal.reflect.DirectMethodHandleAccessor.invoke(DirectMethodHandleAccessor.java:103)
at java.base/java.lang.reflect.Method.invoke(Method.java:580)
at org.testng.internal.invokers.MethodInvocationHelper.invokeMethod(MethodInvocationHelper.java:141)
at org.testng.internal.invokers.TestInvoker.invokeMethod(TestInvoker.java:687)
at org.testng.internal.invokers.TestInvoker.invokeTestMethod(TestInvoker.java:230)
at org.testng.internal.invokers.MethodRunner.runInSequence(MethodRunner.java:63)
at org.testng.internal.invokers.TestInvoker$MethodInvocationAgent.invoke(TestInvoker.java:995)
at org.testng.internal.invokers.TestInvoker.invokeTestMethods(TestInvoker.java:203)
at org.testng.internal.invokers.TestMethodWorker.invokeTestMethods(TestMethodWorker.java:154)
at org.testng.internal.invokers.TestMethodWorker.run(TestMethodWorker.java:134)
at java.base/java.util.ArrayList.forEach(ArrayList.java:1596)
at org.testng.TestRunner.privateRun(TestRunner.java:741)
at org.testng.TestRunner.run(TestRunner.java:616)
at org.testng.SuiteRunner.runTest(SuiteRunner.java:421)
at org.testng.SuiteRunner.runSequentially(SuiteRunner.java:413)
at org.testng.SuiteRunner.privateRun(SuiteRunner.java:373)
at org.testng.SuiteRunner.run(SuiteRunner.java:312)
at org.testng.SuiteRunnerWorker.runSuite(SuiteRunnerWorker.java:52)
at org.testng.SuiteRunnerWorker.run(SuiteRunnerWorker.java:95)
at org.testng.TestNG.runSuitesSequentially(TestNG.java:1274)
at org.testng.TestNG.runSuitesLocally(TestNG.java:1208)
at org.testng.TestNG.runSuites(TestNG.java:1112)
at org.testng.TestNG.run(TestNG.java:1079)
at org.testng.remote.AbstractRemoteTestNG.run(AbstractRemoteTestNG.java:115)
at org.testng.remote.RemoteTestNG.initAndRun(RemoteTestNG.java:293)
at org.testng.remote.RemoteTestNG.main(RemoteTestNG.java:91)
]]>
    </failure>
  </testcase> <!-- tc_cu_16_footerSubEmailOver100Chars -->
  <testcase classname="com.functional.tests.ContactUs_Functional" name="tc_cu_17_homeAfterSubmitGoesHome" time="3.197"/>
  <testcase classname="com.functional.tests.ContactUs_Functional" name="tc_cu_18_submitBlankName" time="0.805">
    <failure type="java.lang.AssertionError" message="Submission should not succeed with blank name. expected [false] but found [true]">
      <![CDATA[java.lang.AssertionError: Submission should not succeed with blank name. expected [false] but found [true]
at org.testng.Assert.fail(Assert.java:111)
at org.testng.Assert.failNotEquals(Assert.java:1590)
at org.testng.Assert.assertFalse(Assert.java:79)
at com.functional.tests.ContactUs_Functional.tc_cu_18_submitBlankName(ContactUs_Functional.java:375)
at java.base/jdk.internal.reflect.DirectMethodHandleAccessor.invoke(DirectMethodHandleAccessor.java:103)
at java.base/java.lang.reflect.Method.invoke(Method.java:580)
at org.testng.internal.invokers.MethodInvocationHelper.invokeMethod(MethodInvocationHelper.java:141)
at org.testng.internal.invokers.TestInvoker.invokeMethod(TestInvoker.java:687)
at org.testng.internal.invokers.TestInvoker.invokeTestMethod(TestInvoker.java:230)
at org.testng.internal.invokers.MethodRunner.runInSequence(MethodRunner.java:63)
at org.testng.internal.invokers.TestInvoker$MethodInvocationAgent.invoke(TestInvoker.java:995)
at org.testng.internal.invokers.TestInvoker.invokeTestMethods(TestInvoker.java:203)
at org.testng.internal.invokers.TestMethodWorker.invokeTestMethods(TestMethodWorker.java:154)
at org.testng.internal.invokers.TestMethodWorker.run(TestMethodWorker.java:134)
at java.base/java.util.ArrayList.forEach(ArrayList.java:1596)
at org.testng.TestRunner.privateRun(TestRunner.java:741)
at org.testng.TestRunner.run(TestRunner.java:616)
at org.testng.SuiteRunner.runTest(SuiteRunner.java:421)
at org.testng.SuiteRunner.runSequentially(SuiteRunner.java:413)
at org.testng.SuiteRunner.privateRun(SuiteRunner.java:373)
at org.testng.SuiteRunner.run(SuiteRunner.java:312)
at org.testng.SuiteRunnerWorker.runSuite(SuiteRunnerWorker.java:52)
at org.testng.SuiteRunnerWorker.run(SuiteRunnerWorker.java:95)
at org.testng.TestNG.runSuitesSequentially(TestNG.java:1274)
at org.testng.TestNG.runSuitesLocally(TestNG.java:1208)
at org.testng.TestNG.runSuites(TestNG.java:1112)
at org.testng.TestNG.run(TestNG.java:1079)
at org.testng.remote.AbstractRemoteTestNG.run(AbstractRemoteTestNG.java:115)
at org.testng.remote.RemoteTestNG.initAndRun(RemoteTestNG.java:293)
at org.testng.remote.RemoteTestNG.main(RemoteTestNG.java:91)
]]>
    </failure>
  </testcase> <!-- tc_cu_18_submitBlankName -->
  <testcase classname="com.functional.tests.ContactUs_Functional" name="tc_cu_19_submitBlankEmail" time="16.183">
    <failure type="java.lang.AssertionError" message="Submission should not succeed with blank email. expected [false] but found [true]">
      <![CDATA[java.lang.AssertionError: Submission should not succeed with blank email. expected [false] but found [true]
at org.testng.Assert.fail(Assert.java:111)
at org.testng.Assert.failNotEquals(Assert.java:1590)
at org.testng.Assert.assertFalse(Assert.java:79)
at com.functional.tests.ContactUs_Functional.tc_cu_19_submitBlankEmail(ContactUs_Functional.java:388)
at java.base/jdk.internal.reflect.DirectMethodHandleAccessor.invoke(DirectMethodHandleAccessor.java:103)
at java.base/java.lang.reflect.Method.invoke(Method.java:580)
at org.testng.internal.invokers.MethodInvocationHelper.invokeMethod(MethodInvocationHelper.java:141)
at org.testng.internal.invokers.TestInvoker.invokeMethod(TestInvoker.java:687)
at org.testng.internal.invokers.TestInvoker.invokeTestMethod(TestInvoker.java:230)
at org.testng.internal.invokers.MethodRunner.runInSequence(MethodRunner.java:63)
at org.testng.internal.invokers.TestInvoker$MethodInvocationAgent.invoke(TestInvoker.java:995)
at org.testng.internal.invokers.TestInvoker.invokeTestMethods(TestInvoker.java:203)
at org.testng.internal.invokers.TestMethodWorker.invokeTestMethods(TestMethodWorker.java:154)
at org.testng.internal.invokers.TestMethodWorker.run(TestMethodWorker.java:134)
at java.base/java.util.ArrayList.forEach(ArrayList.java:1596)
at org.testng.TestRunner.privateRun(TestRunner.java:741)
at org.testng.TestRunner.run(TestRunner.java:616)
at org.testng.SuiteRunner.runTest(SuiteRunner.java:421)
at org.testng.SuiteRunner.runSequentially(SuiteRunner.java:413)
at org.testng.SuiteRunner.privateRun(SuiteRunner.java:373)
at org.testng.SuiteRunner.run(SuiteRunner.java:312)
at org.testng.SuiteRunnerWorker.runSuite(SuiteRunnerWorker.java:52)
at org.testng.SuiteRunnerWorker.run(SuiteRunnerWorker.java:95)
at org.testng.TestNG.runSuitesSequentially(TestNG.java:1274)
at org.testng.TestNG.runSuitesLocally(TestNG.java:1208)
at org.testng.TestNG.runSuites(TestNG.java:1112)
at org.testng.TestNG.run(TestNG.java:1079)
at org.testng.remote.AbstractRemoteTestNG.run(AbstractRemoteTestNG.java:115)
at org.testng.remote.RemoteTestNG.initAndRun(RemoteTestNG.java:293)
at org.testng.remote.RemoteTestNG.main(RemoteTestNG.java:91)
]]>
    </failure>
  </testcase> <!-- tc_cu_19_submitBlankEmail -->
  <testcase classname="com.functional.tests.ContactUs_Functional" name="tc_cu_20_submitBlankSubject" time="1.568">
    <failure type="java.lang.AssertionError" message="Submission should not succeed with blank subject. expected [false] but found [true]">
      <![CDATA[java.lang.AssertionError: Submission should not succeed with blank subject. expected [false] but found [true]
at org.testng.Assert.fail(Assert.java:111)
at org.testng.Assert.failNotEquals(Assert.java:1590)
at org.testng.Assert.assertFalse(Assert.java:79)
at com.functional.tests.ContactUs_Functional.tc_cu_20_submitBlankSubject(ContactUs_Functional.java:401)
at java.base/jdk.internal.reflect.DirectMethodHandleAccessor.invoke(DirectMethodHandleAccessor.java:103)
at java.base/java.lang.reflect.Method.invoke(Method.java:580)
at org.testng.internal.invokers.MethodInvocationHelper.invokeMethod(MethodInvocationHelper.java:141)
at org.testng.internal.invokers.TestInvoker.invokeMethod(TestInvoker.java:687)
at org.testng.internal.invokers.TestInvoker.invokeTestMethod(TestInvoker.java:230)
at org.testng.internal.invokers.MethodRunner.runInSequence(MethodRunner.java:63)
at org.testng.internal.invokers.TestInvoker$MethodInvocationAgent.invoke(TestInvoker.java:995)
at org.testng.internal.invokers.TestInvoker.invokeTestMethods(TestInvoker.java:203)
at org.testng.internal.invokers.TestMethodWorker.invokeTestMethods(TestMethodWorker.java:154)
at org.testng.internal.invokers.TestMethodWorker.run(TestMethodWorker.java:134)
at java.base/java.util.ArrayList.forEach(ArrayList.java:1596)
at org.testng.TestRunner.privateRun(TestRunner.java:741)
at org.testng.TestRunner.run(TestRunner.java:616)
at org.testng.SuiteRunner.runTest(SuiteRunner.java:421)
at org.testng.SuiteRunner.runSequentially(SuiteRunner.java:413)
at org.testng.SuiteRunner.privateRun(SuiteRunner.java:373)
at org.testng.SuiteRunner.run(SuiteRunner.java:312)
at org.testng.SuiteRunnerWorker.runSuite(SuiteRunnerWorker.java:52)
at org.testng.SuiteRunnerWorker.run(SuiteRunnerWorker.java:95)
at org.testng.TestNG.runSuitesSequentially(TestNG.java:1274)
at org.testng.TestNG.runSuitesLocally(TestNG.java:1208)
at org.testng.TestNG.runSuites(TestNG.java:1112)
at org.testng.TestNG.run(TestNG.java:1079)
at org.testng.remote.AbstractRemoteTestNG.run(AbstractRemoteTestNG.java:115)
at org.testng.remote.RemoteTestNG.initAndRun(RemoteTestNG.java:293)
at org.testng.remote.RemoteTestNG.main(RemoteTestNG.java:91)
]]>
    </failure>
  </testcase> <!-- tc_cu_20_submitBlankSubject -->
  <testcase classname="com.functional.tests.ContactUs_Functional" name="tc_cu_21_feedbackSubmits" time="0.958"/>
  <testcase classname="com.functional.tests.ContactUs_Functional" name="tc_cu_22_submitValidCredentials" time="0.703"/>
  <testcase classname="com.functional.tests.ContactUs_Functional" name="tc_cu_23_submitInvalidCredentials" time="16.005">
    <failure type="java.lang.AssertionError" message="Invalid credentials should not yield success message. expected [false] but found [true]">
      <![CDATA[java.lang.AssertionError: Invalid credentials should not yield success message. expected [false] but found [true]
at org.testng.Assert.fail(Assert.java:111)
at org.testng.Assert.failNotEquals(Assert.java:1590)
at org.testng.Assert.assertFalse(Assert.java:79)
at com.functional.tests.ContactUs_Functional.tc_cu_23_submitInvalidCredentials(ContactUs_Functional.java:440)
at java.base/jdk.internal.reflect.DirectMethodHandleAccessor.invoke(DirectMethodHandleAccessor.java:103)
at java.base/java.lang.reflect.Method.invoke(Method.java:580)
at org.testng.internal.invokers.MethodInvocationHelper.invokeMethod(MethodInvocationHelper.java:141)
at org.testng.internal.invokers.TestInvoker.invokeMethod(TestInvoker.java:687)
at org.testng.internal.invokers.TestInvoker.invokeTestMethod(TestInvoker.java:230)
at org.testng.internal.invokers.MethodRunner.runInSequence(MethodRunner.java:63)
at org.testng.internal.invokers.TestInvoker$MethodInvocationAgent.invoke(TestInvoker.java:995)
at org.testng.internal.invokers.TestInvoker.invokeTestMethods(TestInvoker.java:203)
at org.testng.internal.invokers.TestMethodWorker.invokeTestMethods(TestMethodWorker.java:154)
at org.testng.internal.invokers.TestMethodWorker.run(TestMethodWorker.java:134)
at java.base/java.util.ArrayList.forEach(ArrayList.java:1596)
at org.testng.TestRunner.privateRun(TestRunner.java:741)
at org.testng.TestRunner.run(TestRunner.java:616)
at org.testng.SuiteRunner.runTest(SuiteRunner.java:421)
at org.testng.SuiteRunner.runSequentially(SuiteRunner.java:413)
at org.testng.SuiteRunner.privateRun(SuiteRunner.java:373)
at org.testng.SuiteRunner.run(SuiteRunner.java:312)
at org.testng.SuiteRunnerWorker.runSuite(SuiteRunnerWorker.java:52)
at org.testng.SuiteRunnerWorker.run(SuiteRunnerWorker.java:95)
at org.testng.TestNG.runSuitesSequentially(TestNG.java:1274)
at org.testng.TestNG.runSuitesLocally(TestNG.java:1208)
at org.testng.TestNG.runSuites(TestNG.java:1112)
at org.testng.TestNG.run(TestNG.java:1079)
at org.testng.remote.AbstractRemoteTestNG.run(AbstractRemoteTestNG.java:115)
at org.testng.remote.RemoteTestNG.initAndRun(RemoteTestNG.java:293)
at org.testng.remote.RemoteTestNG.main(RemoteTestNG.java:91)
]]>
    </failure>
  </testcase> <!-- tc_cu_23_submitInvalidCredentials -->
</testsuite> <!-- Default test -->
